<?xml version="1.0" ?>
<!-- =================================================================================== -->
<!-- |    This document was autogenerated by xacro from hyrecro_testPlugin.xacro       | -->
<!-- |    EDITING THIS FILE BY HAND IS NOT RECOMMENDED                                 | -->
<!-- =================================================================================== -->
<robot name="hyrecro">
  <gazebo reference="hyrecro">
    <static>true</static>
  </gazebo>
  <material name="black">
    <color rgba="0.0 0.0 0.0 1.0"/>
  </material>
  <material name="blue">
    <color rgba="0.0 0.0 0.8 1.0"/>
  </material>
  <material name="green">
    <color rgba="0.0 0.8 0.0 1.0"/>
  </material>
  <material name="grey">
    <color rgba="0.2 0.2 0.2 1.0"/>
  </material>
  <material name="orange">
    <color rgba="1.0 0.4235294117647059 0.0392156862745098 1.0"/>
  </material>
  <material name="brown">
    <color rgba="0.8705882352941177 0.8117647058823529 0.7647058823529411 1.0"/>
  </material>
  <material name="red">
    <color rgba="0.8 0.0 0.0 1.0"/>
  </material>
  <material name="white">
    <color rgba="1.0 1.0 1.0 1.0"/>
  </material>
  <!--LINKS DECLARATION-->
  <link name="base_link"/>
  <link name="joint_1A"/>
  <link name="joint_2A"/>
  <link name="theta_A"/>
  <link name="joint_1B"/>
  <link name="joint_2B"/>
  <link name="theta_B"/>
  <link name="plat_1A">
    <inertial>
      <origin rpy="0.0 0.0 0.0" xyz="0.0 0.0 0.0"/>
      <mass value="1.0"/>
      <inertia ixx="0.005" ixy="0.0" ixz="0.0" iyy="0.005" iyz="0.0" izz="0.005"/>
    </inertial>
    <visual>
      <origin rpy="0.0 0.0 0.0" xyz="0.0 0.0 0.0"/>
      <geometry>
        <box size="0.1 0.1 0.01"/>
      </geometry>
      <material name="grey"/>
    </visual>
    <collision>
      <origin rpy="0.0 0.0 0.0" xyz="0.0 0.0 0.0"/>
      <geometry>
        <box size="0.1 0.1 0.01"/>
      </geometry>
    </collision>
  </link>
  <link name="prism_1A">
    <inertial>
      <origin rpy="0.0 0.0 0.0" xyz="0.0 0.0 0.0"/>
      <mass value="1.0"/>
      <inertia ixx="0.005" ixy="0.0" ixz="0.0" iyy="0.005" iyz="0.0" izz="0.005"/>
    </inertial>
    <visual>
      <origin rpy="0.0 0.0 0.0" xyz="0.0 0.0 0.0"/>
      <geometry>
        <box size="0.02 0.02 0.15"/>
      </geometry>
      <material name="white"/>
    </visual>
    <collision>
      <origin rpy="0.0 0.0 0.0" xyz="0.0 0.0 0.0"/>
      <geometry>
        <box size="0.02 0.02 0.15"/>
      </geometry>
    </collision>
  </link>
  <link name="prism_2A">
    <inertial>
      <origin rpy="0.0 0.0 0.0" xyz="0.0 0.0 0.0"/>
      <mass value="1.0"/>
      <inertia ixx="0.005" ixy="0.0" ixz="0.0" iyy="0.005" iyz="0.0" izz="0.005"/>
    </inertial>
    <visual>
      <origin rpy="0.0 0.0 0.0" xyz="0.0 0.0 0.0"/>
      <geometry>
        <box size="0.02 0.02 0.15"/>
      </geometry>
      <material name="grey"/>
    </visual>
    <collision>
      <origin rpy="0.0 0.0 0.0" xyz="0.0 0.0 0.0"/>
      <geometry>
        <box size="0.02 0.02 0.15"/>
      </geometry>
    </collision>
  </link>
  <link name="plat_2A">
    <inertial>
      <origin rpy="0.0 0.0 0.0" xyz="0.0 0.0 0.0"/>
      <mass value="1.0"/>
      <inertia ixx="0.005" ixy="0.0" ixz="0.0" iyy="0.005" iyz="0.0" izz="0.005"/>
    </inertial>
    <visual>
      <origin rpy="0.0 0.0 0.0" xyz="0.0 0.0 0.0"/>
      <geometry>
        <box size="0.1 0.1 0.01"/>
      </geometry>
      <material name="grey"/>
    </visual>
    <collision>
      <origin rpy="0.0 0.0 0.0" xyz="0.0 0.0 0.0"/>
      <geometry>
        <box size="0.1 0.1 0.01"/>
      </geometry>
    </collision>
  </link>
  <link name="hip">
    <inertial>
      <origin rpy="0.0 0.0 0.0" xyz="0.0 0.0 0.0"/>
      <mass value="1.0"/>
      <inertia ixx="0.005" ixy="0.0" ixz="0.0" iyy="0.005" iyz="0.0" izz="0.005"/>
    </inertial>
    <visual>
      <origin rpy="0.0 0.0 0.0" xyz="0.0 0.0 0.0"/>
      <geometry>
        <box size="0.25 0.1 0.01"/>
      </geometry>
      <material name="white"/>
    </visual>
    <collision>
      <origin rpy="0.0 0.0 0.0" xyz="0.0 0.0 0.0"/>
      <geometry>
        <box size="0.25 0.1 0.01"/>
      </geometry>
    </collision>
  </link>
  <link name="plat_2B">
    <inertial>
      <origin rpy="0.0 0.0 0.0" xyz="0.0 0.0 0.0"/>
      <mass value="1.0"/>
      <inertia ixx="0.005" ixy="0.0" ixz="0.0" iyy="0.005" iyz="0.0" izz="0.005"/>
    </inertial>
    <visual>
      <origin rpy="0.0 0.0 0.0" xyz="0.0 0.0 0.0"/>
      <geometry>
        <box size="0.1 0.1 0.01"/>
      </geometry>
      <material name="grey"/>
    </visual>
    <collision>
      <origin rpy="0.0 0.0 0.0" xyz="0.0 0.0 0.0"/>
      <geometry>
        <box size="0.1 0.1 0.01"/>
      </geometry>
    </collision>
  </link>
  <link name="prism_2B">
    <inertial>
      <origin rpy="0.0 0.0 0.0" xyz="0.0 0.0 0.0"/>
      <mass value="1.0"/>
      <inertia ixx="0.005" ixy="0.0" ixz="0.0" iyy="0.005" iyz="0.0" izz="0.005"/>
    </inertial>
    <visual>
      <origin rpy="0.0 0.0 0.0" xyz="0.0 0.0 0.0"/>
      <geometry>
        <box size="0.02 0.02 0.15"/>
      </geometry>
      <material name="grey"/>
    </visual>
    <collision>
      <origin rpy="0.0 0.0 0.0" xyz="0.0 0.0 0.0"/>
      <geometry>
        <box size="0.02 0.02 0.15"/>
      </geometry>
    </collision>
  </link>
  <link name="prism_1B">
    <inertial>
      <origin rpy="0.0 0.0 0.0" xyz="0.0 0.0 0.0"/>
      <mass value="1.0"/>
      <inertia ixx="0.005" ixy="0.0" ixz="0.0" iyy="0.005" iyz="0.0" izz="0.005"/>
    </inertial>
    <visual>
      <origin rpy="0.0 0.0 0.0" xyz="0.0 0.0 0.0"/>
      <geometry>
        <box size="0.02 0.02 0.15"/>
      </geometry>
      <material name="white"/>
    </visual>
    <collision>
      <origin rpy="0.0 0.0 0.0" xyz="0.0 0.0 0.0"/>
      <geometry>
        <box size="0.02 0.02 0.15"/>
      </geometry>
    </collision>
  </link>
  <link name="plat_1B">
    <inertial>
      <origin rpy="0.0 0.0 0.0" xyz="0.0 0.0 0.0"/>
      <mass value="1.0"/>
      <inertia ixx="0.005" ixy="0.0" ixz="0.0" iyy="0.005" iyz="0.0" izz="0.005"/>
    </inertial>
    <visual>
      <origin rpy="0.0 0.0 0.0" xyz="0.0 0.0 0.0"/>
      <geometry>
        <box size="0.1 0.1 0.01"/>
      </geometry>
      <material name="grey"/>
    </visual>
    <collision>
      <origin rpy="0.0 0.0 0.0" xyz="0.0 0.0 0.0"/>
      <geometry>
        <box size="0.1 0.1 0.01"/>
      </geometry>
    </collision>
  </link>
  <!--JOINTS DECLARATION-->
  <!-- A -->
  <joint name="base_link_plat_1A" type="fixed">
    <parent link="base_link"/>
    <child link="plat_1A"/>
    <origin rpy="0.0 0.0 0.0" xyz="0.0 0.0 0.005"/>
  </joint>
  <joint name="q1" type="revolute">
    <parent link="plat_1A"/>
    <child link="joint_1A"/>
    <axis xyz="0.0 0.0 1.0"/>
    <origin rpy="1.5707963267948966 0.0 0.0" xyz="0.0 0.0 0.035"/>
    <limit effort="100" lower="-1.5707963267948966" upper="1.5707963267948966" velocity="0.1"/>
  </joint>
  <joint name="prism_1A_joint_1A" type="fixed">
    <parent link="joint_1A"/>
    <child link="prism_1A"/>
    <origin rpy="-1.5707963267948966 0.0 0.0" xyz="0.0 0.075 0.0"/>
  </joint>
  <joint name="passive_prismatic_A" type="prismatic">
    <parent link="prism_1A"/>
    <child link="prism_2A"/>
    <axis xyz="0.0 0.0 1.0"/>
    <origin rpy="0.0 0.0 0.0" xyz="0.0 0.0 0.05"/>
    <limit effort="100" lower="-0.025" upper="0.025" velocity="0.1"/>
  </joint>
  <joint name="q2" type="revolute">
    <parent link="prism_2A"/>
    <child link="joint_2A"/>
    <origin rpy="1.5707963267948966 0.0 0.0" xyz="0.0 0.0 0.075"/>
    <axis xyz="0.0 0.0 1.0"/>
    <limit effort="100" lower="-1.5707963267948966" upper="1.5707963267948966" velocity="0.1"/>
  </joint>
  <joint name="joint_2_plat_2A" type="fixed">
    <origin rpy="-1.5707963267948966 0.0 0.0" xyz="0.0 0.035 0.0"/>
    <parent link="joint_2A"/>
    <child link="plat_2A"/>
  </joint>
  <joint name="q3" type="revolute">
    <parent link="plat_2A"/>
    <child link="theta_A"/>
    <origin rpy="0.0 0.0 0.0" xyz="0.0 0.0 0.015"/>
    <axis xyz="0.0 0.0 1.0"/>
    <limit effort="100" lower="-3.141592653589793" upper="3.141592653589793" velocity="0.1"/>
  </joint>
  <joint name="theta_A_hip" type="fixed">
    <parent link="theta_A"/>
    <child link="hip"/>
    <origin rpy="0.0 0.0 0.0" xyz="0.075 0.0 0.0"/>
  </joint>
  <!-- B -->
  <joint name="q4" type="revolute">
    <parent link="hip"/>
    <child link="theta_B"/>
    <origin rpy="0.0 0.0 0.0" xyz="0.075 0.0 0.0"/>
    <axis xyz="0.0 0.0 1.0"/>
    <limit effort="100" lower="-3.141592653589793" upper="3.141592653589793" velocity="0.1"/>
  </joint>
  <joint name="theta_B_plat_2B" type="fixed">
    <parent link="theta_B"/>
    <child link="plat_2B"/>
    <origin rpy="0.0 0.0 0.0" xyz="0.0 0.0 -0.015"/>
  </joint>
  <joint name="q5" type="revolute">
    <parent link="plat_2B"/>
    <child link="joint_2B"/>
    <origin rpy="1.5707963267948966 0.0 0.0" xyz="0.0 0.0 -0.035"/>
    <axis xyz="0.0 0.0 1.0"/>
    <limit effort="100" lower="-1.5707963267948966" upper="1.5707963267948966" velocity="0.1"/>
  </joint>
  <joint name="joint_2B_prism_2B" type="fixed">
    <parent link="joint_2B"/>
    <child link="prism_2B"/>
    <origin rpy="-1.5707963267948966 0.0 0.0" xyz="0.0 -0.075 0.0"/>
  </joint>
  <joint name="passive_prismatic_B" type="prismatic">
    <parent link="prism_2B"/>
    <child link="prism_1B"/>
    <axis xyz="0.0 0.0 1.0"/>
    <origin rpy="0.0 0.0 0.0" xyz="0.0 0.0 -0.05"/>
    <limit effort="100" lower="-0.025" upper="0.025" velocity="0.1"/>
  </joint>
  <joint name="q6" type="revolute">
    <parent link="prism_1B"/>
    <child link="joint_1B"/>
    <origin rpy="1.5707963267948966 0.0 0.0" xyz="0.0 0.0 -0.075"/>
    <axis xyz="0.0 0.0 1.0"/>
    <limit effort="100" lower="-1.5707963267948966" upper="1.5707963267948966" velocity="0.1"/>
  </joint>
  <joint name="joint_1B_plat_1B" type="fixed">
    <parent link="joint_1B"/>
    <child link="plat_1B"/>
    <origin rpy="-1.5707963267948966 0.0 0.0" xyz="0.0 -0.035 0.0"/>
  </joint>
  <gazebo reference="hyrecro">
    <material>Gzebo/Blue/</material>
  </gazebo>
  <joint name="os1_sensor_mount_joint" type="fixed">
    <origin rpy="0.0 0.0 0.0" xyz="0.0 0.0 0.04175"/>
    <parent link="hip"/>
    <child link="os1_sensor"/>
  </joint>
  <link name="os1_sensor">
    <inertial>
      <mass value="0.33"/>
      <origin rpy="0 0 0" xyz="0 0 0.0365"/>
      <inertia ixx="0.000241148" ixy="0" ixz="0" iyy="0.000241148" iyz="0" izz="0.000264"/>
    </inertial>
    <collision name="base_collision">
      <origin rpy="0 0 0" xyz="0 0 0.0365"/>
      <geometry>
        <cylinder length="0.073" radius="0.04"/>
      </geometry>
    </collision>
    <visual name="base_visual">
      <origin rpy="0 0 1.5707" xyz="0 0 0.0"/>
      <geometry>
        <!--<mesh filename="package://ouster_description/meshes/os1_64.dae" /> -->
        <cylinder length="0.073" radius="0.04"/>
      </geometry>
    </visual>
  </link>
  <link name="os1_imu"/>
  <link name="os1_lidar"/>
  <joint name="os1_sensor_imu_link_joint" type="fixed">
    <parent link="os1_sensor"/>
    <child link="os1_imu"/>
    <origin rpy="0 0 0" xyz="0.006253 -0.011775 0.007645"/>
  </joint>
  <gazebo reference="os1_imu">
    </gazebo>
  <joint name="os1_sensor_lidar_link_joint" type="fixed">
    <parent link="os1_sensor"/>
    <child link="os1_lidar"/>
    <origin rpy="0 0 0" xyz="0.0 0.0 0.03618"/>
  </joint>
  <!-- Gazebo requires the ouster_gazebo_plugins package -->
  <gazebo reference="os1_sensor">
    <sensor name="os1_sensor-OS1-128" type="ray">
      <pose>0 0 0 0 0 0</pose>
      <visualize>false</visualize>
      <update_rate>10</update_rate>
      <ray>
        <scan>
          <horizontal>
            <samples>512</samples>
            <resolution>1</resolution>
            <min_angle>-3.141592653589793</min_angle>
            <max_angle>3.141592653589793</max_angle>
          </horizontal>
          <vertical>
            <samples>128</samples>
            <resolution>1</resolution>
            <min_angle>-0.3979</min_angle>
            <max_angle>0.3979</max_angle>
          </vertical>
        </scan>
        <range>
          <min>0.1</min>
          <max>10.0</max>
          <resolution>0.03</resolution>
        </range>
      </ray>
      <plugin filename="libgazebo_ros_ouster_laser.so" name="gazebo_ros_laser_controller">
        <topicName>/os1/pointCloud</topicName>
        <frameName>os1_sensor</frameName>
        <min_range>0.1</min_range>
        <max_range>10.0</max_range>
        <gaussianNoise>0.008</gaussianNoise>
      </plugin>
    </sensor>
  </gazebo>
  <!-- IMU -->
  <gazebo>
    <plugin filename="libhector_gazebo_ros_imu.so" name="imu_controller">
      <robotNamespace>/</robotNamespace>
      <updateRate>100.0</updateRate>
      <bodyName>os1_imu</bodyName>
      <topicName>/os1/imu</topicName>
      <accelDrift>0.005 0.005 0.005</accelDrift>
      <accelGaussianNoise>0.005 0.005 0.005</accelGaussianNoise>
      <rateDrift>0.005 0.005 0.005 </rateDrift>
      <rateGaussianNoise>0.005 0.005 0.005 </rateGaussianNoise>
      <headingDrift>0.005</headingDrift>
      <headingGaussianNoise>0.005</headingGaussianNoise>
    </plugin>
  </gazebo>
  <gazebo>
    <plugin filename="libtest_plugin.so" name="test_plugin"/>
  </gazebo>
</robot>
<!-- A CONFIGURATION -->
